Workbook

Sheet raw_data
A1: Functional | B1: Metal | C1: System | D1: Type | E1: Steps | F1: Converged | G1: Runtime | H1: CPUtime | I1: Memory | J1: TotalEnergy | K1: System | L1: Metal
A2: lda | B2: bulk_Ag | C2: pristine_supercell | D2: main | E2: 13 | F2: Yes | G2: 2682.429 | H2: 4712.849 | I2: 1895540 | J2: -54.617989 | K2: pristine_supercell | L2: bulk_Ag
A3: lda | B3: bulk_Ag | C3: defective_supercell | D3: main | E3: 13 | F3: Yes | G3: 2697.556 | H3: 4732.655 | I3: 1892844 | J3: -51.663879 | K3: defective_supercell | L3: bulk_Ag | M3: =J3-(31/32)*J2 -> 1.2472974
A4: lda | B4: bulk_Al | C4: pristine_supercell | D4: main | E4: 12 | F4: Yes | G4: 1434.413 | H4: 2483.686 | I4: 1220792 | J4: -133.9915 | K4: pristine_supercell | L4: bulk_Al
A5: lda | B5: bulk_Al | C5: defective_supercell | D5: main | E5: 12 | F5: Yes | G5: 1424.552 | H5: 2464.904 | I5: 1220040 | J5: -128.97581 | K5: defective_supercell | L5: bulk_Al | M5: =J5-(31/32)*J4 -> 0.82845215
A6: lda | B6: bulk_Au | C6: pristine_supercell | D6: main | E6: 12 | F6: Yes | G6: 2257.67 | H6: 3917.269 | I6: 1495432 | J6: -121.31066 | K6: pristine_supercell | L6: bulk_Au
A7: lda | B7: bulk_Au | C7: defective_supercell | D7: main | E7: 13 | F7: Yes | G7: 2528.965 | H7: 4427.023 | I7: 1507288 | J7: -116.67987 | K7: defective_supercell | L7: bulk_Au | M7: =J7-(31/32)*J6 -> 0.83983343
A8: lda | B8: bulk_Cu | C8: pristine_supercell | D8: main | E8: 13 | F8: Yes | G8: 2622.448 | H8: 4639.406 | I8: 1423068 | J8: -154.36295 | K8: pristine_supercell | L8: bulk_Cu
A9: lda | B9: bulk_Cu | C9: defective_supercell | D9: main | E9: 16 | F9: Yes | G9: 3266.045 | H9: 5817.745 | I9: 1421516 | J9: -148.02489 | K9: defective_supercell | L9: bulk_Cu | M9: =J9-(31/32)*J8 -> 1.5142092
A10: lda | B10: bulk_Ni | C10: pristine_supercell | D10: main | E10: 15 | F10: Yes | G10: 24518.549 | H10: 41877.75 | I10: 2170652 | J10: -237.47687 | K10: pristine_supercell | L10: bulk_Ni
A11: lda | B11: bulk_Ni | C11: defective_supercell | D11: main | E11: 22 | F11: Yes | G11: 1731.736 | H11: 3110.435 | I11: 2552348 | J11: -228.02185 | K11: defective_supercell | L11: bulk_Ni | M11: =J11-(31/32)*J10 -> 2.0338667
A12: lda | B12: bulk_Pb | C12: pristine_supercell | D12: main | E12: 13 | F12: Yes | G12: 7509.15 | H12: 13782.207 | I12: 3191288 | J12: -136.36581 | K12: pristine_supercell | L12: bulk_Pb
A13: lda | B13: bulk_Pb | C13: defective_supercell | D13: main | E13: 13 | F13: Yes | G13: 7547.797 | H13: 13890.076 | I13: 3180376 | J13: -131.48274 | K13: defective_supercell | L13: bulk_Pb | M13: =J13-(31/32)*J12 -> 0.62163618
A14: lda | B14: bulk_Pd | C14: pristine_supercell | D14: main | E14: 17 | F14: Yes | G14: 6416.275 | H14: 11294.037 | I14: 2385736 | J14: -160.92559 | K14: pristine_supercell | L14: bulk_Pd
A15: lda | B15: bulk_Pd | C15: defective_supercell | D15: main | E15: 24 | F15: Yes | G15: 9316.821 | H15: 16670.848 | I15: 2368348 | J15: -154.11684 | K15: defective_supercell | L15: bulk_Pd | M15: =J15-(31/32)*J14 -> 1.7798205
A16: lda | B16: bulk_Pt | C16: pristine_supercell | D16: main | E16: 12 | F16: Yes | G16: 1668.42 | H16: 2826.132 | I16: 1334756 | J16: -234.57738 | K16: pristine_supercell | L16: bulk_Pt
A17: lda | B17: bulk_Pt | C17: defective_supercell | D17: main | E17: 23 | F17: Yes | G17: 3015.79 | H17: 5266.385 | I17: 1336388 | J17: -225.81153 | K17: defective_supercell | L17: bulk_Pt | M17: =J17-(31/32)*J16 -> 1.4352986
A18: pbe | B18: bulk_Ag | C18: pristine_supercell | D18: main | E18: 14 | F18: Yes | G18: 2966.959 | H18: 9971.003 | I18: 1892092 | J18: -20.589203 | K18: pristine_supercell | L18: bulk_Ag
A19: pbe | B19: bulk_Ag | C19: defective_supercell | D19: main | E19: 14 | F19: Yes | G19: 2923.484 | H19: 5162.143 | I19: 1893728 | J19: -19.30555 | K19: defective_supercell | L19: bulk_Ag | M19: =J19-(31/32)*J18 -> 0.64024061
A20: pbe | B20: bulk_Al | C20: pristine_supercell | D20: main | E20: 19 | F20: Yes | G20: 2439.616 | H20: 4340.594 | I20: 1221396 | J20: -120.61923 | K20: pristine_supercell | L20: bulk_Al
A21: pbe | B21: bulk_Al | C21: defective_supercell | D21: main | E21: 19 | F21: Yes | G21: 2400.526 | H21: 4205.836 | I21: 1220424 | J21: -116.14952 | K21: defective_supercell | L21: bulk_Al | M21: =J21-(31/32)*J20 -> 0.70035169
A22: pbe | B22: bulk_Au | C22: pristine_supercell | D22: main | E22: 12 | F22: Yes | G22: 2430.129 | H22: 4228.356 | I22: 1508276 | J22: -82.346626 | K22: pristine_supercell | L22: bulk_Au
A23: pbe | B23: bulk_Au | C23: defective_supercell | D23: main | E23: 15 | F23: Yes | G23: 2932.856 | H23: 5166.323 | I23: 1509832 | J23: -79.631618 | K23: defective_supercell | L23: bulk_Au | M23: =J23-(31/32)*J22 -> 0.14167571
A24: pbe | B24: bulk_Cu | C24: pristine_supercell | D24: main | E24: 14 | F24: Yes | G24: 2735.365 | H24: 4860.167 | I24: 1423468 | J24: -121.25777 | K24: pristine_supercell | L24: bulk_Cu
A25: pbe | B25: bulk_Cu | C25: defective_supercell | D25: main | E25: 16 | F25: Yes | G25: 3125.009 | H25: 5568.851 | I25: 1421452 | J25: -116.42908 | K25: defective_supercell | L25: bulk_Cu | M25: =J25-(31/32)*J24 -> 1.0393903
A26: pbe | B26: bulk_Ni | C26: pristine_supercell | D26: main | E26: 15 | F26: Yes | G26: 5697.233 | H26: 10084.729 | I26: 1993404 | J26: -205.42309 | K26: pristine_supercell | L26: bulk_Ni
A27: pbe | B27: bulk_Ni | C27: defective_supercell | D27: main | E27: 21 | F27: Yes | G27: 8382.333 | H27: 15014.102 | I27: 1975212 | J27: -197.53132 | K27: defective_supercell | L27: bulk_Ni | M27: =J27-(31/32)*J26 -> 1.4723
A28: pbe | B28: bulk_Pb | C28: pristine_supercell | D28: main | E28: 14 | F28: Yes | G28: 7849.582 | H28: 14474.343 | I28: 3192820 | J28: -113.86923 | K28: pristine_supercell | L28: bulk_Pb
A29: pbe | B29: bulk_Pb | C29: defective_supercell | D29: main | E29: 14 | F29: Yes | G29: 7879.493 | H29: 14518.043 | I29: 3191028 | J29: -110.09251 | K29: defective_supercell | L29: bulk_Pb | M29: =J29-(31/32)*J28 -> 0.2183049
A30: pbe | B30: bulk_Pd | C30: pristine_supercell | D30: main | E30: 18 | F30: Yes | G30: 6868.977 | H30: 12113.3 | I30: 2386260 | J30: -119.7913 | K30: pristine_supercell | L30: bulk_Pd
A31: pbe | B31: bulk_Pd | C31: defective_supercell | D31: main | E31: 26 | F31: Yes | G31: 10179.175 | H31: 18200.01 | I31: 2366704 | J31: -114.97898 | K31: defective_supercell | L31: bulk_Pd | M31: =J31-(31/32)*J30 -> 1.0688495
A32: pbe | B32: bulk_Pt | C32: pristine_supercell | D32: main | E32: 15 | F32: Yes | G32: 1982.76 | H32: 3394.687 | I32: 1335980 | J32: -193.59259 | K32: pristine_supercell | L32: bulk_Pt
A33: pbe | B33: bulk_Pt | C33: defective_supercell | D33: main | E33: 20 | F33: Yes | G33: 2744.208 | H33: 4732.098 | I33: 1332512 | J33: -186.8612 | K33: defective_supercell | L33: bulk_Pt | M33: =J33-(31/32)*J32 -> 0.68162596
A34: scan | B34: bulk_Ag | C34: pristine_supercell | D34: main | E34: 18 | F34: Yes | G34: 4292.368 | H34: 7771.715 | I34: 1928568 | J34: -938.33276 | K34: pristine_supercell | L34: bulk_Ag
A35: scan | B35: bulk_Ag | C35: defective_supercell | D35: main | E35: 20 | F35: Yes | G35: 4779.77 | H35: 8649.258 | I35: 1926216 | J35: -908.13296 | K35: defective_supercell | L35: bulk_Ag | M35: =J35-(31/32)*J34 -> 0.87690314
A36: scan | B36: bulk_Al | C36: pristine_supercell | D36: main | E36: 21 | F36: Yes | G36: 226.42 | H36: 616.616 | I36: 3062096 | J36: -247.77588 | K36: pristine_supercell | L36: bulk_Al
A37: scan | B37: bulk_Al | C37: defective_supercell | D37: main | E37: N/A | F37: Missing | G37: N/A | H37: N/A | I37: N/A | J37: -239.18748 | K37: defective_supercell | L37: bulk_Al | M37: =J37-(31/32)*J36 -> 0.84540406
A38: scan | B38: bulk_Au | C38: pristine_supercell | D38: main | E38: 15 | F38: Yes | G38: 3636.516 | H38: 6535.994 | I38: 1542996 | J38: -2191.2223 | K38: pristine_supercell | L38: bulk_Au
A39: scan | B39: bulk_Au | C39: defective_supercell | D39: main | E39: 18 | F39: Yes | G39: 4152.147 | H39: 7535.56 | I39: 1555496 | J39: -2122.3365 | K39: defective_supercell | L39: bulk_Au | M39: =J39-(31/32)*J38 -> 0.41011784
A40: scan | B40: bulk_Cu | C40: pristine_supercell | D40: main | E40: 20 | F40: Yes | G40: 4515.667 | H40: 8128.554 | I40: 1465156 | J40: -487.66544 | K40: pristine_supercell | L40: bulk_Cu
...

Sheet Formation_Energies
A1: Solids | B1: LDA | C1: PBE | D1: SCAN | E1: r2SCAN | F1: LAK | G1: Expt | H1: N
A2: Ag | B2: {=INDEX(raw_data!J:J,(ROW()-1)*2+1) - (31/32)*INDEX(raw_data!J:J,(ROW()-1)*2)} -> 1.2472974 | C2: {=INDEX(raw_data!J:J,(ROW()-ROW($B$2))*2+18+1) - (31/32)*INDEX(raw_data!J:J,(ROW()-ROW($B$2))*2+18)} -> 0.64024061 | D2: {=INDEX(raw_data!J:J,(ROW()-ROW($B$2))*2+34+1) - (31/32)*INDEX(raw_data!J:J,(ROW()-ROW($B$2))*2+34)} -> 0.87690314 | E2: {=INDEX(raw_data!J:J,(ROW()-ROW($B$2))*2+50+1) - (31/32)*INDEX(raw_data!J:J,(ROW()-ROW($B$2))*2+50)} -> 0.79333369 | F2: {=INDEX(raw_data!J:J,(ROW()-ROW($B$2))*2+66+1) - (31/32)*INDEX(raw_data!J:J,(ROW()-ROW($B$2))*2+66)} -> 0.26357962 | H2: 5
A3: Al | B3: {=INDEX(raw_data!J:J,(ROW()-1)*2+1) - (31/32)*INDEX(raw_data!J:J,(ROW()-1)*2)} -> 0.82845215 | C3: {=INDEX(raw_data!J:J,(ROW()-ROW($B$2))*2+18+1) - (31/32)*INDEX(raw_data!J:J,(ROW()-ROW($B$2))*2+18)} -> 0.70035169 | D3: {=INDEX(raw_data!J:J,(ROW()-ROW($B$2))*2+34+1) - (31/32)*INDEX(raw_data!J:J,(ROW()-ROW($B$2))*2+34)} -> 0.84540406 | E3: {=INDEX(raw_data!J:J,(ROW()-ROW($B$2))*2+50+1) - (31/32)*INDEX(raw_data!J:J,(ROW()-ROW($B$2))*2+50)} -> 1.0524301 | F3: {=INDEX(raw_data!J:J,(ROW()-ROW($B$2))*2+66+1) - (31/32)*INDEX(raw_data!J:J,(ROW()-ROW($B$2))*2+66)} -> 0.90313998 | H3: 7
A4: Au | B4: {=INDEX(raw_data!J:J,(ROW()-1)*2+1) - (31/32)*INDEX(raw_data!J:J,(ROW()-1)*2)} -> 0.83983343 | C4: {=INDEX(raw_data!J:J,(ROW()-ROW($B$2))*2+18+1) - (31/32)*INDEX(raw_data!J:J,(ROW()-ROW($B$2))*2+18)} -> 0.14167571 | D4: {=INDEX(raw_data!J:J,(ROW()-ROW($B$2))*2+34+1) - (31/32)*INDEX(raw_data!J:J,(ROW()-ROW($B$2))*2+34)} -> 0.41011784 | E4: {=INDEX(raw_data!J:J,(ROW()-ROW($B$2))*2+50+1) - (31/32)*INDEX(raw_data!J:J,(ROW()-ROW($B$2))*2+50)} -> 0.31795995 | F4: {=INDEX(raw_data!J:J,(ROW()-ROW($B$2))*2+66+1) - (31/32)*INDEX(raw_data!J:J,(ROW()-ROW($B$2))*2+66)} -> -0.37886515 | H4: 6
A5: Cu | B5: {=INDEX(raw_data!J:J,(ROW()-1)*2+1) - (31/32)*INDEX(raw_data!J:J,(ROW()-1)*2)} -> 1.5142092 | C5: {=INDEX(raw_data!J:J,(ROW()-ROW($B$2))*2+18+1) - (31/32)*INDEX(raw_data!J:J,(ROW()-ROW($B$2))*2+18)} -> 1.0393903 | D5: {=INDEX(raw_data!J:J,(ROW()-ROW($B$2))*2+34+1) - (31/32)*INDEX(raw_data!J:J,(ROW()-ROW($B$2))*2+34)} -> 1.4007522 | E5: {=INDEX(raw_data!J:J,(ROW()-ROW($B$2))*2+50+1) - (31/32)*INDEX(raw_data!J:J,(ROW()-ROW($B$2))*2+50)} -> 1.2727198 | F5: {=INDEX(raw_data!J:J,(ROW()-ROW($B$2))*2+66+1) - (31/32)*INDEX(raw_data!J:J,(ROW()-ROW($B$2))*2+66)} -> 1.0356041 | H5: 4
A6: Ni | B6: {=INDEX(raw_data!J:J,(ROW()-1)*2+1) - (31/32)*INDEX(raw_data!J:J,(ROW()-1)*2)} -> 2.0338667 | C6: {=INDEX(raw_data!J:J,(ROW()-ROW($B$2))*2+18+1) - (31/32)*INDEX(raw_data!J:J,(ROW()-ROW($B$2))*2+18)} -> 1.4723 | D6: {=INDEX(raw_data!J:J,(ROW()-ROW($B$2))*2+34+1) - (31/32)*INDEX(raw_data!J:J,(ROW()-ROW($B$2))*2+34)} -> 1.7588619 | E6: {=INDEX(raw_data!J:J,(ROW()-ROW($B$2))*2+50+1) - (31/32)*INDEX(raw_data!J:J,(ROW()-ROW($B$2))*2+50)} -> 1.6795585 | F6: {=INDEX(raw_data!J:J,(ROW()-ROW($B$2))*2+66+1) - (31/32)*INDEX(raw_data!J:J,(ROW()-ROW($B$2))*2+66)} -> 1.3483393 | H6: 1
A7: Pb | B7: {=INDEX(raw_data!J:J,(ROW()-1)*2+1) - (31/32)*INDEX(raw_data!J:J,(ROW()-1)*2)} -> 0.62163618 | C7: {=INDEX(raw_data!J:J,(ROW()-ROW($B$2))*2+18+1) - (31/32)*INDEX(raw_data!J:J,(ROW()-ROW($B$2))*2+18)} -> 0.2183049 | D7: {=INDEX(raw_data!J:J,(ROW()-ROW($B$2))*2+34+1) - (31/32)*INDEX(raw_data!J:J,(ROW()-ROW($B$2))*2+34)} -> 0.26792213 | E7: {=INDEX(raw_data!J:J,(ROW()-ROW($B$2))*2+50+1) - (31/32)*INDEX(raw_data!J:J,(ROW()-ROW($B$2))*2+50)} -> 0.25888446 | F7: {=INDEX(raw_data!J:J,(ROW()-ROW($B$2))*2+66+1) - (31/32)*INDEX(raw_data!J:J,(ROW()-ROW($B$2))*2+66)} -> -0.30237338 | H7: 8
A8: Pd | B8: {=INDEX(raw_data!J:J,(ROW()-1)*2+1) - (31/32)*INDEX(raw_data!J:J,(ROW()-1)*2)} -> 1.7798205 | C8: {=INDEX(raw_data!J:J,(ROW()-ROW($B$2))*2+18+1) - (31/32)*INDEX(raw_data!J:J,(ROW()-ROW($B$2))*2+18)} -> 1.0688495 | D8: {=INDEX(raw_data!J:J,(ROW()-ROW($B$2))*2+34+1) - (31/32)*INDEX(raw_data!J:J,(ROW()-ROW($B$2))*2+34)} -> 1.3237293 | E8: {=INDEX(raw_data!J:J,(ROW()-ROW($B$2))*2+50+1) - (31/32)*INDEX(raw_data!J:J,(ROW()-ROW($B$2))*2+50)} -> 1.2266045 | F8: {=INDEX(raw_data!J:J,(ROW()-ROW($B$2))*2+66+1) - (31/32)*INDEX(raw_data!J:J,(ROW()-ROW($B$2))*2+66)} -> 0.59062461 | H8: 2
A9: Pt | B9: {=INDEX(raw_data!J:J,(ROW()-1)*2+1) - (31/32)*INDEX(raw_data!J:J,(ROW()-1)*2)} -> 1.4352986 | C9: {=INDEX(raw_data!J:J,(ROW()-ROW($B$2))*2+18+1) - (31/32)*INDEX(raw_data!J:J,(ROW()-ROW($B$2))*2+18)} -> 0.68162596 | D9: {=INDEX(raw_data!J:J,(ROW()-ROW($B$2))*2+34+1) - (31/32)*INDEX(raw_data!J:J,(ROW()-ROW($B$2))*2+34)} -> 0.81587673 | E9: {=INDEX(raw_data!J:J,(ROW()-ROW($B$2))*2+50+1) - (31/32)*INDEX(raw_data!J:J,(ROW()-ROW($B$2))*2+50)} -> 0.86185439 | F9: {=INDEX(raw_data!J:J,(ROW()-ROW($B$2))*2+66+1) - (31/32)*INDEX(raw_data!J:J,(ROW()-ROW($B$2))*2+66)} -> 0.1845539 | H9: 3

Sheet Printing_form_energies
A1: Solids | B1: LDA | C1: PBE | D1: SCAN | E1: r2SCAN | F1: LAK | G1: Recommended Expt | H1: MAE per metal | I1: Std dev (STDEV.P)
A2: Ni | B2: 2.0338667 | C2: 1.4723 | D2: 1.7588619 | E2: 1.6795585 | F2: 1.3483393 | G2: 1.8 | H2: 0.23496141 | I2: 0.23760735
A3: Pd | B3: 1.7798205 | C3: 1.0688495 | D3: 1.3237293 | E3: 1.2266045 | F3: 0.59062461 | G3: 1.85 | H3: 0.65207432 | I3: 0.3848963
A4: Pt | B4: 1.4352986 | C4: 0.68162596 | D4: 0.81587673 | E4: 0.86185439 | F4: 0.1845539 | G4: 1.35 | H4: 0.58827751 | I4: 0.40009553
A5: Cu | B5: 1.5142092 | C5: 1.0393903 | D5: 1.4007522 | E5: 1.2727198 | F5: 1.0356041 | G5: 1.06 | H5: 0.21053736 | I5: 0.1914883
A6: Ag | B6: 1.2472974 | C6: 0.64024061 | D6: 0.87690314 | E6: 0.79333369 | F6: 0.26357962 | G6: 0.94 | H6: 0.29864807 | I6: 0.32028755
A7: Au | B7: 0.83983343 | C7: 0.14167571 | D7: 0.41011784 | E7: 0.31795995 | F7: -0.37886515 | G7: 0.94 | H7: 0.67385565 | I7: 0.39599547
A8: Al | B8: 0.82845215 | C8: 0.70035169 | D8: 0.85 | E8: 1.0524301 | F8: 0.90313998 | G8: 0.67 | H8: 47.949534 | I8: 95.496949
A9: Pb | B9: 0.62163618 | C9: 0.2183049 | D9: 0.26792213 | E9: 0.25888446 | F9: -0.30237338 | G9: 0.58 | H9: 0.38377961 | I9: 0.29588617
B10: 0.18138829 | C10: 0.41099559 | D10: 30.16133 | E10: 0.3646193 | F10: 0.75145963

Sheet table_plot
A1: Solids | B1: LDA | C1: PBE | D1: SCAN | E1: r2SCAN | F1: LAK | G1: Recommended Expt
A2: Ni | B2: 2.0338667 | C2: 1.4723 | D2: 1.7588619 | E2: 1.6795585 | F2: 1.3483393 | G2: 1.8
A3: Pd | B3: 1.7798205 | C3: 1.0688495 | D3: 1.3237293 | E3: 1.2266045 | F3: 0.59062461 | G3: 1.85
A4: Pt | B4: 1.4352986 | C4: 0.68162596 | D4: 0.81587673 | E4: 0.86185439 | F4: 0.1845539 | G4: 1.35
A5: Cu | B5: 1.5142092 | C5: 1.0393903 | D5: 1.4007522 | E5: 1.2727198 | F5: 1.0356041 | G5: 1.06
A6: Ag | B6: 1.2472974 | C6: 0.64024061 | D6: 0.87690314 | E6: 0.79333369 | F6: 0.26357962 | G6: 0.94
A7: Au | B7: 0.83983343 | C7: 0.14167571 | D7: 0.41011784 | E7: 0.31795995 | F7: -0.37886515 | G7: 0.94
A8: Al | B8: 0.82845215 | C8: 0.70035169 | D8: 0.84540406 | E8: 1.0524301 | F8: 0.90313998 | G8: 0.67
A9: Pb | B9: 0.62163618 | C9: 0.2183049 | D9: 0.26792213 | E9: 0.25888446 | F9: -0.30237338 | G9: 0.58

Sheet Mod_Form_Energies
A1: Solids | B1: LDA | C1: PBE | D1: SCAN | E1: r2SCAN | F1: LAK | G1: Expt | H1: Recommended Expt | I1: Std dev (STDEV.P) | J1: MAE per metal | K1: N
A2: Ni | B2: 2.0338667 | C2: 1.4723 | D2: 1.7588619 | E2: 1.6795585 | F2: 1.3483393 | G2: 1.2, 1.40, 1.45, 1.68, 1.79, 1.80 | H2: 1.8 | I2: =_xlfn.STDEV.P(B2:F2) -> 0.23760735 | J2: =AVERAGE(ABS(B2-$H2),ABS(C2-$H2),ABS(D2-$H2),ABS(E2-$H2),ABS(F2-$H2)) -> 0.23496141 | K2: 1
A3: Pd | B3: 1.7798205 | C3: 1.0688495 | D3: 1.3237293 | E3: 1.2266045 | F3: 0.59062461 | G3: 1.4, 1.5, 1.85, 1.87 | H3: 1.85 | I3: =_xlfn.STDEV.P(B3:F3) -> 0.3848963 | J3: =AVERAGE(ABS(B3-$H3),ABS(C3-$H3),ABS(D3-$H3),ABS(E3-$H3),ABS(F3-$H3)) -> 0.65207432 | K3: 2
A4: Pt | B4: 1.4352986 | C4: 0.68162596 | D4: 0.81587673 | E4: 0.86185439 | F4: 0.1845539 | G4: 1.15, 1.26, 1.32, 1.35, 1.44, 1.60, 1.70 | H4: 1.35 | I4: =_xlfn.STDEV.P(B4:F4) -> 0.40009553 | J4: =AVERAGE(ABS(B4-$H4),ABS(C4-$H4),ABS(D4-$H4),ABS(E4-$H4),ABS(F4-$H4)) -> 0.58827751 | K4: 3
A5: Cu | B5: 1.5142092 | C5: 1.0393903 | D5: 1.4007522 | E5: 1.2727198 | F5: 1.0356041 | G5: 0.92, 1.00, 1.04, 1.27, 1.30, 1.42, 1.49 | H5: 1.06 | I5: =_xlfn.STDEV.P(B5:F5) -> 0.1914883 | J5: =AVERAGE(ABS(B5-$H5),ABS(C5-$H5),ABS(D5-$H5),ABS(E5-$H5),ABS(F5-$H5)) -> 0.21053736 | K5: 4
A6: Ag | B6: 1.2472974 | C6: 0.64024061 | D6: 0.87690314 | E6: 0.79333369 | F6: 0.26357962 | G6: 1.06, 1.11, 1.19, 1.31 | H6: 0.94 | I6: =_xlfn.STDEV.P(B6:F6) -> 0.32028755 | J6: =AVERAGE(ABS(B6-$H6),ABS(C6-$H6),ABS(D6-$H6),ABS(E6-$H6),ABS(F6-$H6)) -> 0.29864807 | K6: 5
A7: Au | B7: 0.83983343 | C7: 0.14167571 | D7: 0.41011784 | E7: 0.31795995 | F7: -0.37886515 | G7: 0.85, 0.89, 0.93, 0.95, 0.98, 1.00, 1.02 | H7: 0.94 | I7: =_xlfn.STDEV.P(B7:F7) -> 0.39599547 | J7: =AVERAGE(ABS(B7-$H7),ABS(C7-$H7),ABS(D7-$H7),ABS(E7-$H7),ABS(F7-$H7)) -> 0.67385565 | K7: 6
A8: Al | B8: 0.82845215 | C8: 0.70035169 | D8: 0.84540406 | E8: 1.0524301 | F8: 0.90313998 | G8: 0.60, 0.66, 0.68, 0.77, 0.80, 0.82, 1.17 | H8: 0.67 | I8: =_xlfn.STDEV.P(B8:F8) -> 0.11437564 | J8: =AVERAGE(ABS(B8-$H8),ABS(C8-$H8),ABS(D8-$H8),ABS(E8-$H8),ABS(F8-$H8)) -> 0.19595559 | K8: 7
A9: Pb | B9: 0.62163618 | C9: 0.2183049 | D9: 0.26792213 | E9: 0.25888446 | F9: -0.30237338 | G9: 0.47, 0.58, 0.70 | H9: 0.58 | I9: =_xlfn.STDEV.P(B9:F9) -> 0.29588617 | J9: =AVERAGE(ABS(B9-$H9),ABS(C9-$H9),ABS(D9-$H9),ABS(E9-$H9),ABS(F9-$H9)) -> 0.38377961 | K9: 8
A10: MAE per functional | B10: {=AVERAGE(ABS(B2:B9 - $H$2:$H$9))} -> 0.18138829 | C10: {=AVERAGE(ABS(C2:C9 - $H$2:$H$9))} -> 0.41099559 | D10: {=AVERAGE(ABS(D2:D9 - $H$2:$H$9))} -> 0.31534315 | E10: {=AVERAGE(ABS(E2:E9 - $H$2:$H$9))} -> 0.3646193 | F10: {=AVERAGE(ABS(F2:F9 - $H$2:$H$9))} -> 0.75145963
